<?xml version="1.0" encoding="UTF-8"?>
<!-- Generated by org.testng.reporters.JUnitReportReporter -->
<testsuite hostname="lap1154" failures="1" tests="6" name="com.TestCases.VerifyUserLoginTest" time="34.833" errors="0" timestamp="2023-03-22T05:13:45 IST" skipped="4">
  <testcase classname="com.TestCases.VerifyUserLoginTest" name="verify_invalid_User_invalid_password_login" time="12.541"/>
  <system-out/>
  <testcase classname="com.TestCases.VerifyUserLoginTest" name="verify_invalid_User_valid_password_login" time="7.607">
    <skipped/>
  </testcase> <!-- verify_invalid_User_valid_password_login -->
  <system-out/>
  <testcase classname="com.TestCases.VerifyUserLoginTest" name="verify_invalid_User_valid_password_login" time="7.702">
    <failure message="expected [Logins] but found [Login]" type="java.lang.AssertionError">
      <![CDATA[java.lang.AssertionError: expected [Logins] but found [Login]
at org.testng.Assert.fail(Assert.java:110)
at org.testng.Assert.failNotEquals(Assert.java:1413)
at org.testng.Assert.assertEqualsImpl(Assert.java:149)
at org.testng.Assert.assertEquals(Assert.java:131)
at org.testng.Assert.assertEquals(Assert.java:655)
at org.testng.Assert.assertEquals(Assert.java:665)
at com.TestCases.VerifyUserLoginTest.verify_invalid_User_valid_password_login(VerifyUserLoginTest.java:60)
at java.base/jdk.internal.reflect.NativeMethodAccessorImpl.invoke0(Native Method)
at java.base/jdk.internal.reflect.NativeMethodAccessorImpl.invoke(NativeMethodAccessorImpl.java:77)
at java.base/jdk.internal.reflect.DelegatingMethodAccessorImpl.invoke(DelegatingMethodAccessorImpl.java:43)
at java.base/java.lang.reflect.Method.invoke(Method.java:568)
at org.testng.internal.invokers.MethodInvocationHelper.invokeMethod(MethodInvocationHelper.java:135)
at org.testng.internal.invokers.TestInvoker.invokeMethod(TestInvoker.java:673)
at org.testng.internal.invokers.TestInvoker.retryFailed(TestInvoker.java:262)
at org.testng.internal.invokers.MethodRunner.runInSequence(MethodRunner.java:62)
at org.testng.internal.invokers.TestInvoker$MethodInvocationAgent.invoke(TestInvoker.java:945)
at org.testng.internal.invokers.TestInvoker.invokeTestMethods(TestInvoker.java:193)
at org.testng.internal.invokers.TestMethodWorker.invokeTestMethods(TestMethodWorker.java:146)
at org.testng.internal.invokers.TestMethodWorker.run(TestMethodWorker.java:128)
at java.base/java.util.ArrayList.forEach(ArrayList.java:1511)
at org.testng.TestRunner.privateRun(TestRunner.java:808)
at org.testng.TestRunner.run(TestRunner.java:603)
at org.testng.SuiteRunner.runTest(SuiteRunner.java:429)
at org.testng.SuiteRunner.runSequentially(SuiteRunner.java:423)
at org.testng.SuiteRunner.privateRun(SuiteRunner.java:383)
at org.testng.SuiteRunner.run(SuiteRunner.java:326)
at org.testng.SuiteRunnerWorker.runSuite(SuiteRunnerWorker.java:52)
at org.testng.SuiteRunnerWorker.run(SuiteRunnerWorker.java:95)
at org.testng.TestNG.runSuitesSequentially(TestNG.java:1249)
at org.testng.TestNG.runSuitesLocally(TestNG.java:1169)
at org.testng.TestNG.runSuites(TestNG.java:1092)
at org.testng.TestNG.run(TestNG.java:1060)
at org.testng.remote.AbstractRemoteTestNG.run(AbstractRemoteTestNG.java:115)
at org.testng.remote.RemoteTestNG.initAndRun(RemoteTestNG.java:251)
at org.testng.remote.RemoteTestNG.main(RemoteTestNG.java:77)
]]>
    </failure>
  </testcase> <!-- verify_invalid_User_valid_password_login -->
  <system-out/>
  <testcase classname="com.TestCases.VerifyUserLoginTest" name="verify_invalid_User_valid_password_login" time="6.983">
    <skipped/>
  </testcase> <!-- verify_invalid_User_valid_password_login -->
  <system-out/>
  <testcase classname="com.TestCases.VerifyUserLoginTest" name="verify_valid_User_invalid_Password_login">
    <skipped/>
  </testcase> <!-- verify_valid_User_invalid_Password_login -->
  <system-out/>
  <testcase classname="com.TestCases.VerifyUserLoginTest" name="verify_valid_User_Login">
    <skipped/>
  </testcase> <!-- verify_valid_User_Login -->
  <system-out/>
</testsuite> <!-- com.TestCases.VerifyUserLoginTest -->
